Workbook

Sheet Buku Kode
B1: BUKU KODE — ANALISIS SENTIMEN PUBLIK TERHADAP DJP
B3: Dokumen ini adalah buku kode (codebook) dalam pengertian Neuendorf (2017): definisi operasional lengkap yang memungkinkan orang lain melakukan pengodean atas data yang sama dan memperoleh hasil yang serupa. Dibaca seluruhnya sebelum pengodean dimulai, lalu dipatuhi sampai selesai. Buku kode tidak boleh diubah di tengah pengodean; kasus yang tidak tercakup dicatat pada kolom Catatan, diputuskan sekaligus di akhir, lalu baris terdampak disapu ulang.
B5: BAGIAN 1 — DEFINISI UNIT
B6: Krippendorff (2019, Bab 5) membedakan tiga jenis unit yang harus dinyatakan terpisah. Kelalaian menyatakannya adalah sumber ketidaksepakatan yang sering tidak disadari.
B7: Unit sampling | C7: Satu postingan utuh pada platform Threads, yaitu satu unggahan beserta seluruh isinya. Balasan terhadap postingan tidak termasuk dan tidak dikumpulkan.
B8: Unit rekam / pengodean | C8: Sama dengan unit sampling, yaitu satu postingan utuh menerima satu label. Konsekuensinya diuraikan pada Bagian 2.3.
B9: Unit konteks | C9: Teks postingan itu sendiri. Pelabel TIDAK membuka tautan, TIDAK menelusuri utas, dan TIDAK mencari riwayat akun penulis. Seluruh keputusan diambil hanya dari teks yang tampak pada kolom Isi Thread. Aturan ini menjaga agar seluruh pelabel bekerja atas informasi yang sama.
B10: Yang dikeluarkan | C10: Emoji, tautan, dan tanda pagar tidak dinilai tersendiri, tetapi boleh dipakai sebagai petunjuk nada apabila teksnya ambigu.
B12: BAGIAN 2 — DEFINISI KONSEPTUAL
B13: Liu (2015, Definisi 2.7) merumuskan opini sebagai quintuple (e, a, s, h, t): entitas sasaran, aspek dari entitas itu, sentimen, pemegang opini, dan waktu. Proyek ini menetapkan kelimanya sebagai berikut.
B14: e — Entitas | C14: Direktorat Jenderal Pajak sebagai institusi.
B15: a — Aspek | C15: GENERAL. Artinya yang dinilai adalah sikap terhadap DJP secara keseluruhan, bukan terhadap aspek tertentu. Kolom Aspek pada lembar pengodean bersifat opsional dan hanya untuk keperluan pengembangan berbasis aspek pada tahap berikutnya; kolom itu tidak memengaruhi label.
B16: s — Sentimen | C16: Positif, Negatif, atau Netral. Ditambah kategori Tidak Relevan untuk unit yang tidak memuat opini terhadap e sama sekali.
B17: h — Pemegang opini | C17: Penulis postingan. Bila penulis mengutip sikap orang lain, yang dinilai tetap sikap penulis, bukan sikap orang yang dikutip.
B18: t — Waktu | C18: Dicatat bila tersedia; tidak memengaruhi label.
B20: 2.1 Cakupan entitas
B21: Sikap terhadap ketiga hal berikut dihitung sebagai sikap terhadap DJP.
B22: a. Kebijakan dan aturan | C22: Ketentuan perpajakan yang dijalankan DJP: tarif, kewajiban lapor, aturan pemotongan, ketentuan atas transaksi tertentu.
B23: b. Layanan dan proses | C23: Interaksi wajib pajak dengan DJP: pelayanan kantor, SP2DK, pemeriksaan, sistem dan aplikasi perpajakan.
B24: c. Pegawai DJP | C24: Pegawai dalam kapasitasnya sebagai aparat DJP, termasuk gaji, tunjangan, mutasi, dan integritas.
B25: Di luar ketiganya bukan entitas yang dinilai. Sikap terhadap pemerintah secara umum, terhadap instansi lain, atau terhadap kehidupan pribadi penulis tidak dihitung sebagai sikap terhadap DJP.
B27: 2.2 Definisi tiap nilai sentimen
B28: POSITIF | C28: Penulis menyatakan penilaian yang mendukung, memuji, membela, mempercayai, atau berterima kasih kepada DJP, kebijakannya, layanannya, atau pegawainya.
B29: NEGATIF | C29: Penulis menyatakan penilaian yang mengkritik, mengeluh, menuduh, menyindir, menolak, atau menyatakan ketidakpercayaan terhadap DJP, kebijakannya, layanannya, atau pegawainya.
B30: NETRAL | C30: Penulis menyampaikan informasi, penjelasan, laporan fakta, atau pertanyaan mengenai DJP tanpa penilaian yang berpihak. Termasuk di sini teks yang muatan positif dan negatifnya benar-benar seimbang. Liu (2015) menyebut kategori ini sebagai ungkapan netral, bukan ketiadaan opini.
B31: TIDAK RELEVAN | C31: Teks tidak menyinggung DJP menurut Bagian 2.1 sama sekali, sehingga tidak ada entitas e yang dapat dinilai. Contohnya ucapan selamat, perkenalan diri, atau cerita keluarga.
B32: Keempat nilai bersifat lengkap dan saling terpisah (exhaustive dan mutually exclusive) sebagaimana disyaratkan Neuendorf (2017). Setiap unit menerima tepat satu nilai.
B34: 2.3 Batas yang harus disadari pelabel
B35: Liu (2015, Asumsi 3.1) menyatakan bahwa klasifikasi pada tingkat dokumen mengandaikan satu dokumen memuat opini atas satu entitas dari satu pemegang opini. Liu secara khusus mencatat asumsi ini berlaku baik untuk ulasan produk, tetapi sering tidak berlaku untuk postingan forum dan blog, karena penulisnya dapat menilai beberapa entitas sekaligus. Data proyek ini berasal dari media sosial, sehingga termasuk jenis yang berisiko. Aturan penanganannya ada pada Bagian 3, butir M1 dan M2.
B37: BAGIAN 3 — ATURAN KEPUTUSAN
B38: Dijalankan berurutan. Berhenti pada aturan pertama yang cocok.
B39: Langkah 1 | C39: Apakah teks menyinggung DJP menurut Bagian 2.1? Bila tidak sama sekali, beri TIDAK RELEVAN dan berhenti.
B40: Langkah 2 | C40: Apakah penulis menyampaikan penilaian, atau hanya menyampaikan informasi atau pertanyaan?
B41: Langkah 3 | C41: Terapkan definisi Bagian 2.2. Bila masih ragu, gunakan aturan khusus di bawah.
B43: Aturan khusus
B44: K1. Fakta yang berimplikasi | C44: Liu (2015) menegaskan kalimat yang menyatakan fakta pun dapat menyiratkan sentimen bila fakta itu jelas diinginkan atau tidak diinginkan. Karena itu, pertanyaannya BUKAN apakah teks memuat kata bermuatan, melainkan apakah penulis menyampaikan fakta tersebut untuk menyatakan sesuatu yang tidak diinginkan TENTANG DJP. Bila ya, beri NEGATIF meski tanpa kata bernada negatif.
B45: K2. Cerita untuk mengedukasi | C45: Cerita tentang orang yang kena denda atau diperiksa TIDAK otomatis negatif. Bila cerita dipakai untuk menjelaskan aturan dan penulis tidak menyalahkan DJP, beri NETRAL. Bila cerita dipakai untuk menyalahkan DJP atau aturannya, beri NEGATIF. Pembeda utamanya: siapa yang ditempatkan sebagai pihak yang keliru.
B46: K3. Pertanyaan murni | C46: Teks yang hanya bertanya, tanpa keluhan atau sindiran yang menempel, diberi NETRAL.
B47: K4. Sentimen rasional | C47: Liu (2015, Definisi 2.5) membedakan sentimen rasional dari sentimen emosional. Sikap yang disampaikan dengan nada datar dan berdasar pertimbangan tetap dihitung sebagai sentimen. Ketiadaan luapan emosi bukan alasan memberi NETRAL.
B48: K5. Kritik ke luar DJP | C48: Keluhan mengenai korupsi atau penggunaan uang pajak oleh pihak di luar DJP diberi TIDAK RELEVAN, KECUALI penulis menarik kesimpulan mengenai DJP atau mengenai kemauannya membayar pajak. Bila ya, beri NEGATIF.
...

Sheet Relabeling
A1: ID | B1: No Asli | C1: Username | D1: Tanggal | E1: Isi Thread | F1: Label Lama | G1: Konflik Label | H1: LABEL BARU | I1: ASPEK (opsional) | J1: Catatan
A2: 1 | B2: 1 | C2: _vinetta | D2: 2026-03-03 | E2: Qadarullah semalam terima kabar ini Selamat atas promosinya suamiku sayang. Semoga selalu langkahmu dimudahkan Allah swt.. Semangat untuk keluarga kecil kita yaa Aku selalu sayang sama kamu mas. Selama ini dari awal menikah sampai 3 tahun LDM-nya masih ketemu seminggu sekali. Sekarang belum ada bayangan sih bakal gimana Dan aku lagi tubel di STAN. Jadi semoga aku bisa menyelesaikan studiku dengan baik juga, sambil jaga bayi mungil inii Mohon doanya | F2: positif
A3: 2 | B3: 2 | C3: nrachman77 | D3: 2026-03-24 | E3: Saya punya teman orang pajak. Tiap hari ketika kerja selalu was was, kerja ga enak hati dan pikirannya suka ga fokus. Salah satu yang bikin ia tenang jika ibadah tepat waktu, rata2 pegawai pajak itu rajin ibadah. Sholat tepat waktu suka sedekah dll. Dengan harapan bisa menyeimbangkan dengan pekerjaan utamanya. Saya ga banyak komentar, ia tau tentang hadis pemungut pajak namun belum bisa move ke pekerjaan lain. Barangkali disini ada yang pernah kerja sebagai pegawai pajak dan gmn cr bsa pindah | F3: negatif
A4: 3 | B4: 3 | C4: nafkahnation.dx | D4: 2026-04-19 | E4: Temen gw kerja di KPP Pratama. Bagian pelayanan. Bukan pemeriksa. Bukan konsultan pajak. Tiap minggu dia liat org dateng, bawa map berisi sertifikat rumah warisan orang tua. Dateng buat urus pajak balik nama.Wajah mereka sama semua: kaget, bingung, marah.Dia sebut satu angka yg bikin gw mules:"90% dari mereka harusnya bayar NOL. Bukan puluhan juta. Tapi gak ada yg kasih tau." Ada satu surat. Namanya S** P**. Dan hampir gak ada warga yg tau. | F4: negatif
A5: 4 | B5: 4 | C5: ikramlabs | D5: 2025-04-21 | E5: Tadi habis nyimak rekan instansi gue nyeritain pengalamannya dia kerja di Ditjen Pajak. Salah satu Wajib Pajak (WP) yang dia urus datengin ruang kerjanya di sore hari banget menjelang maghrib sambil bawa kardus yang besarnya mencolok dan berat banget bersama dengan konsultan pajaknya dia. Kantor udah sepi, temen-temennya udah pada pulang juga. Pas temen gue ini liat tuh kardus isinya uang tunai pecahan seratus ribuan penuh! Si konsultan bilang "mas ini buat kamu, kasih juga si bos ya". Singkat cerita rekan gue itu nolak ya. Konsultan langsung putus asa dong, duit segitu ditolak ya mau ngapain lagi coba? Tapi nggak lama si konsultan bilang, "waktu itu saya pernah ngurus ginian juga di Jambi, pegawainya sama sok-nya kayak kamu. Terakhir saya dapet info istri sama anaknya meninggal". Temen gue jawab dengan statement yang gue udah sangat paham sebenernya, tapi kalau gue di posisi dia saat itu pasti udah naik darah duluan lah. Gila aja nih orang bawa-bawa keluarga dan ngancem nyawa segala. Jadilah statement "biasa" yang udah gue tahu itu berasa jauh lebih menyentuh hati dengernya. Dia bilang, "kalau Allah takdirkan saya atau keluarga saya meninggal di hari tertentu, maka siapapun nggak bisa mencegah dan nggak bisa juga mempercepatnya | F5: positif
A6: 5 | B6: 5 | C6: sherlyajawes | D6: 2026-04-07 | E6: Semalam aku cerita ke suamiku soal aturan pajak marketplace yg baru. Dan nemu insight menarik… 🤦🏻‍♀️ Aku 🙋🏻 Suami 🤦🏻‍♀️ : sistemnya DJP ini aneh, bukannya fokus ke penjual yg udah 500jt keatas, tapi yg dibawah 500jt juga wajib isi pernyataan omzet kalo gak mau kepotong pajak 🙋🏻: ohh gituu, jadi semua penjual walaupun omzet dibawah 500jt tetep ngisi? 🙋🏻 : intinya DJP mau mendeteksi pedagang sejak dini. Mau omzetmu msh 5jt kek, 10jt kek, pas km ngumpulin pernyataan dan data penghasilan otomatis mereka tau km punya usaha di marketplace. Kalo suatu saat nanti bisnismu berkembang mencapai 500jt, maka kewajibanmu sebagai wajib pajak auto aktif. Sistem defaultnya adalah potong pajak, makanya pernyataan omzet menjadi satu syarat supaya km gak dipotong pajak dan shopee pny dasar hukum knp km gak dipotong pajak. Bonusnya, DJP dpt datamu jg. | F6: netral
A7: 6 | B7: 6 | C7: hafizrizalm | D7: 2026-04-30 | E7: Temen gue orang pajak. Dia bilang gini: "Bro, orang Indonesia itu takut warisan bukan krn rebutan. Tapi krn PAJAKNYA." Gue tanya: "Emang warisan kena pajak?" Dia ketawa bisa rausan Juta BRO. Satu kalimat dia yg bikin gue langsung telpon nyokap bahas sertifikat rumah. | F7: negatif
A8: 7 | B8: 7 | C8: jnsjnsjnsjnsjnss | D8: 2026-12-05 | E8: Lulus STAN Tahun 2018, penempatan Kemenkeu, penempatan homebase dari 2019-sekarang, seru-seru aja. Bangun pagi bisa santai sempat olahraga, masuk-pulang tenggo, bisa sambil kuliah, no complaints sih sampai detik ini. Makasih STAN | F8: positif
A9: 8 | B9: 8 | C9: irwandiferry | D9: 2026-07-16 | E9: Gaji pegawai DJP itu gak setinggi yg kt bayangin, termasuk tinggi memang dibanding banyak instansi yang lain, tapi gak sampai buat diri lu jadi auto sultan dsb. untuk level staff, gaji mereka dibawah PNS pemda DKI, dibawah BI, dibawah OJK, dan masih kalah dengan banyak gaji staf di berbagai BUMN. Resiko yg mereka hadapi gak ringan, keselamatan terancam, beberapa meninggal dalam tugas, dianggap ancaman oleh masyarakat, belum lagi sistem mutasi seluruh indonesia | F9: positif
A10: 9 | B10: 9 | C10: sapto_su | D10: 2026-08-04 | E10: Hari ini di DJP ada pelantikan atas promosi/mutasi pejabat eselon IV. Saya lihat daftarnya, ada beberapa AR yang dipromosikan dengan lokasi penempatan yang relatif jauh, misalnya dari Jakarta ke Atambua atau Jayapura, bahkan dari Medan ke Waingapu. Jadi ingat, dulu pernah ada seorang AR menelepon saya di malam hari, menanyakan apakah ada lowongan di tempat saya. Ternyata beliau termasuk dalam SK promosi yang baru saja keluar, dipromosikan menjadi Kepala Seksi di salah satu KPP di Papua. | F10: netral
A11: 10 | B11: 10 | C11: agusmaulana122019 | D11: 2025-07-28 | E11: Saya ex-pajak. Saya kabari ga enaknya jadi pegawai pajak: 1. Mutasi Nasional, saya pernah di papua 6 tahun. Harus siap jauh dari keluarga. Pengelolaan keluarga jadi rumit. Mahal pula. 2. Kerja sebagai pemberi sanksi. Waktu itu jabatan saya pemeriksa. Pengusaha indo banyak yang ga siap sama pengujian. Ga ngerti kalo bisnis itu wajib didokumentasikan. Memberi sanksi sama pengusaha nakal adalah kebanggaan, tapi sama yang ga ngerti, jadinya perasaan bersalah. 3. Nanti saya terusin. | F11: negatif
A12: 11 | B12: 11 | C12: virdahusna | D12: 2026-01-16 | E12: Hi kenalin aku Virda seorang istri yang ikut bersama suami bekerja berteman dengan mutasi 🌻 | F12: netral
A13: 12 | B13: 12 | C13: iqbalhabibi90 | D13: 2024-10-15 | E13: Gak layak org pajak dikasih gaji besar Sektor swasta yg harusnya dikasih insentif sebesar mungkin krn swastalah yg nyata² menggerakkan roda ekonomi negara Kalo pendapatan sektor pajak capai target, itu sebenernya bukan prestasi mereka, tp prestasi para pekerja dan pengusaha Kok bisa²nya pegawai pajak yg digelontor bonus prestasi | F13: negatif
A14: 13 | B14: 13 | C14: terajanajunu | D14: 2026-07-22 | E14: Tugas DJP tu skrg sulit ya Pajak dan kerelaan org bayar pajak makin tergerus akibat oknum2 yg menggunakan uang pajak rakyat serampangan Gimana org mau rela bayar pajak kalau gak ada lagi trust yg tercpta | F14: negatif | G14: Ya
A15: 14 | B15: 14 | C15: pra7z | E15: Resign dari DJP tuh salah satu perks-nya ya bisa "dijual" "ex-DJP"-nya. Terima kasih DJP. 🏃‍♂️🏃‍♂️🏃‍♂️ | F15: positif
A16: 15 | B16: 15 | C16: jdp_1107 | E16: Rame thread DJP resign berjamaah. Untuk para senior yang sudah resign dari DJP apakah ada yang menyesal? Ternyata kerjaan di luar DJP tidak seindah yang dibayangkan. Dan ternyata di DJP tidak seburuk itu? | F16: netral
A17: 16 | B17: 16 | C17: wyomilliron3 | D17: 2025-05-15 | E17: Isn’t that so the truth. Prefect is boring, it’s the struggle that makes us who we are. -DJP 2025 | F17: positif
A18: 17 | B18: 17 | C18: wolandgarro | D18: 2025-08-25 | E18: 1/ Konflik kepentingan di DJP & KPP udah di level memprihatinkan. Temen gua eks KPP cerita: banyak petugas pajak yang… istrinya ternyata konsultan pajak. Kebayang gak? Di satu sisi dia punya power, di sisi lain istrinya main di bisnis yang bisa “ngurusin” WP. Dia tau titik lemah di mana, tau cara mainin, dan tau gimana deal. Polanya? Mereka nembak angka asal2an. WP ditekan, lalu ujungnya “ketemu di tengah” dgnn kontribusi. Mereka nyaman menekan semua orang karena sistemnya ngasih ruang buat itu. | F18: negatif
A19: 18 | B19: 18 | C19: lesssummernotes | D19: 2025-07-30 | E19: Djp adalah institusi pengawasan kepatuhan perpajakan. Ada institusi lain yang mengelola penerimaan negara. DJPONLINE adalah aplikasi yg digunakan DJP utk 2024 dan sebelumnya. Coretax, aplikasi terintegrasi yg digunakan DJP sejak 2025. | F19: netral
A20: 19 | B20: 19 | C20: unaisatuzzahro | D20: 2026-04-04 | E20: Dulu, suami adalah pegawai Kemen*** D*P dengan THP 2 digit. Setelah 14 tahun, akhirnya memutuskan untuk mengundurkan diri dengan hormat setelah maju mundur, beberapa kali mengambil cuti. Waktu itu, rumah masih ngontrak dan ada tabungan yang hanya cukup buat DP rumah di daerah tangsel. Sudah 5 tahun berlalu... | F20: netral
A21: 20 | B21: 20 | C21: by_marhentin.ika | D21: 2025-06-20 | E21: 22 tahun yg lalu resmi penempatan di DJP, di KPP Tamansari Dua, sbg pelaksana di Seksi PPh Badan. Lokasi kantornya masih di ruko2 di Jln Gajah Mada, Jakarta Barat. Sekarang KPPnya sudah dilikuidasi, hanya tertinggal KPP Jakarta Tamansari. 22 tahun terlewati, udah ketemu ribuan wajib pajak dan ngalamin ribuan cerita. Pernah dimaki-maki sampe nangis, pernah juga dibawain es jeruk setermos gede sama wajib pajak pas piket SPT Tahunan, sampe dijodohin sama anaknya wajib pajak juga pernah😁 | F21: positif
A22: 21 | B22: 21 | C22: shesarhikmainsana | D22: 2026-06-22 | E22: Baru resign dari DJP setelah masa kerja 17th. Enaknya kerja apaan ya? Ada sih usaha. Tp masih banyak waktu luangnya. Need advice dong? Ga bisa diem soalnya. | F22: netral
A23: 22 | B23: 22 | C23: silvesteralan_ | D23: 2026-10-05 | E23: Rame nih algoritma nunjukin utas tentang PKN STAN, PNS Kemenkeu, dan Resign. Pas banget saya Lulus STAN 2018, Jadi PNS Kemenkeu 2019 penempatan kantor pusat, resign 2024. Banyak hal yang bisa dishare, yang selam ini cuma diomongin ke org terdekat aja, dan kebetulan circle saya juga ex pns kemenkeu juga rata2 | F23: netral
A24: 23 | B24: 23 | C24: fitraharis.batupahat | D24: 2026-12-03 | E24: Ternyata di thread ini lumayan banyak cerita tentang DJP dan seputarnya ya. Saya juga alumni DJP yang resign 2023 lalu. Pengen cerita sedikit tapi ini malam ganjil. Kalo agak rame insyaa Allah besok siang kita cerita ya. Saya janji yang diceritain tentang pegawai yang baik2 aja | F24: positif
A25: 24 | B25: 24 | C25: ilhaamrmdn | D25: 2026-09-05 | E25: Lagi ramai bahas STAN, jadi pengen sedikit cerita kenapa akhirnya aku memutuskan resign setelah 3 tahun kerja, padahal sudah di 'Kemensultan | F25: netral
A26: 25 | B26: 25 | C26: yeshafdrna | D26: 2025-08-11 | E26: Punya sepupu ASN di Kementerian eselon yang katanya THP paling tinggi se Indonesia. Usia 34thn udah Kepala Seksi, sering dapat penghargaan (gak pernah di post di sosmed taunya dari tante yg post di group wa keluarga 🤭), istrinya dokter spesialis minor, praktek 3 hari aja/minggu sisanya ngurus anak2. Mobil sepupuku keluaran thn 90an beli bekas, kacanya masih diputar. Mobil istrinya city car beli bekas juga. Istrinya gak pernah pake tas branded pakenya tas UMKM | F26: positif
A27: 26 | B27: 26 | C27: aariakbr | D27: 2026-03-07 | E27: Kalau sesuai hadist: Pegawai DJP dan bea cukai tidak akan masuk surga | F27: (kosong) | G27: Ya
A28: 27 | B28: 27 | C28: ander95bnbn | D28: 2026-05-28 | E28: TUKIN pegawai pajak emang rata-rata gede banget ya? Di DJP, yg level pelaksana aja bisa dapat 5 juta sebulan. | F28: negatif
A29: 28 | B29: 28 | C29: benane_fashion | D29: 2026-04-04 | E29: SYUKURLAH BILA PURBAYA AKAN MENYEIMBANGKAN GAJI PARA ASN DISELURUH KEMENTERIAN DAN LEMBAGA2 PEMERINTAH DI RI. Sudah puluhan tahun, gaji pegawai Kementerian Keuangan secara resmi jauh lebih tinggi dari seluruh kementerian di Republik ini. Apalagi jajaran ditjen Pajak, Bea Cukai dan Perbendaharaan Negara. Alasannya supaya mereka bisa lebih jujur! Bullshit! | F29: negatif
A30: 29 | B30: 29 | C30: meeyaardouli | D30: 2026-04-04 | E30: Hampir mustahil sih…. Gaji pegawai djp tinggi itu tujuannya mencegah brain drain supaya pegawainya ngga pada kabur jadi konsultan, pindah jadi tax manager persh swasta, atau pindah ke pemda yg ga terancam mutasi nasional rutin tiap 2-3 tahun sekali. Kalau ga ada benefit sama sekali dibanding bebannya (termasuk beban hujatan dan doa masuk neraka dri netijen), yakin byk yg resign/pindah pemda, terutama yg pinter2. Risiko ke pengamanan penerimaan negara kalo mereka berbalik mengamankan laba pershn | F30: positif | G30: Ya
A31: 30 | B31: 30 | C31: by_marhentin.ika | D31: 2025-03-16 | E31: Beberapa hari ini dapet DM dr temen2 internal DJP karena postingan saya seputar edukasi pajak muncul di akun mereka. Rata2 menyemangati karena memang ngga banyak pegawai DJP yg nekat muncul di medsos, kenalan bahwa mereka kerja di DJP. Ada 1 DM yg langsung tanya “bu ngga takut kena hujatan di medsos?” | F31: positif | G31: Ya
A32: 31 | B32: 31 | C32: widhingrh | D32: 2026-05-27 | E32: pertama mau disclaimer no offense yak itu yg kerja di DJP mau sebagai AR atau apalah, kan mereka punya KPI atau target untuk pemasukan ke negara, kurang lebih seperti sales gak sih ? kan sama” harus ada pemasuk untuk perusahaan, bedanya ya sales jual produk/jasa, DJP jual kesalahan WP 😭🙏🏻 (soalnya tiap tahun tuh keluarin surat cinta mulu, minta klarifikasi data) | F32: negatif
A33: 32 | B33: 32 | C33: pegawhy_negeri_swasta | D33: 2026-07-16 | E33: Ga sepakat...asumsi saya, Dimana2 djp lebih tinggi thp nya dibanding 80 - 90 persen pemda seindonesia | F33: negatif
A34: 33 | B34: 33 | C34: ekkyarnindi | D34: 2026-07-16 | E34: Saya kerja di instansi pemda, suami di DJP. Belanja pegawai setahun di instansi saya 3,6 miliar untuk 39 pegawai. Suami saya waktu itu masih AR yang punya tim kerja 5-6 orang dengan target pemasukan ke negara lebih 5 miliar selama setahun. Itu artinya gaji 39 orang pegawai di satu instansi pemda itu dibackup dengan kinerja tidak lebih dari 5 orang pegawai DJP. Itu artinya wajar THP mereka lebih tinggi dari instansi lain. | F34: positif
A35: 34 | B35: 34 | C35: cremona_97 | D35: 2025-10-09 | E35: Oo namanya imbalan prestasi kinerja (IPK) di djp... Bukan avanza baru tp kl seken dapet lah | F35: negatif
A36: 35 | B36: 35 | C36: syifaahmgold | D36: 2026-06-30 | E36: Saya di KOMCAD kan lalu di tekan ini itu kak, dari kementerian yg katanya sultan. Tes kesehatan KOMCAD penuh ma-ni-pu-la-si, daripada saya mati kaya yg udh ada...Lalu saya memilih resign sekalian | F36: negatif
A37: 36 | B37: 36 | C37: zeinelarham | E37: Setau saya ASN Kemenkeu DJP paling ramah Ibu dan Anak, seperti ada : ruang Laktasi, kemudahan izin jika anak sakit, ada ruang bermain jika izin bawa anak ke kantor. Jadi ASN yang pas buat perempuan, sepertinya Kemenkeu. Buat perempuan ASN yang di Kemenkeu DJP, jangan resign karena ramah ibu dan anak. entah kalo ASN kementerian lain. | F37: positif
A38: 37 | B38: 37 | C38: pajaksmart | D38: 2026-04-21 | E38: Laporan Kinerja DJP 2025 Larangan Merekam Gak Dibahas niih ?? | F38: negatif
A39: 38 | B39: 38 | C39: accelerationtax | E39: Perspektif Internal DJP: Trigger Undangan bagi Wajib Pajak Orang Pribadi. Tahun lalu, tim kami sempat berdiskusi santai dengan salah satu mantan pegawai DJP. Banyak cerita yang kami dapatkan dari perspektif internal, salah satunya adalah trigger dasar mereka untuk mengundang Wajib Pajak melalui SP2DK, Helicopter View yang menjadi dasar analisis dari suatu grup perusahaan atau perusahaan afiliasi, dan masih banyak lagi. | F39: netral
A40: 39 | B40: 39 | C40: resletingkolor | D40: 2026-07-15 | E40: Tiap ketemu WP, "sy ikhlas bayar kalau uangnya ga dikorupsi". Saya jg setuju Pak..... | F40: negatif
...

Sheet Uji Keandalan Awal
B1: UJI KEANDALAN AWAL
B2: Uji awal (pilot) sesuai Neuendorf (2017): dikerjakan SETELAH membaca buku kode dan SEBELUM pengodean penuh dimulai. 40 unit dipilih acak dari 264 baris. Dua pelabel mengisi kolom masing-masing tanpa saling melihat. Bila hanya ada satu pelabel, isi kolom B pada hari berbeda tanpa melihat kolom A. Bila alpha di bawah 0,667, perbaiki buku kode dan ulangi.
B4: ID | C4: No Asli | D4: Isi Thread | E4: PELABEL A | F4: PELABEL B
B5: 5 | C5: 5 | D5: Semalam aku cerita ke suamiku soal aturan pajak marketplace yg baru. Dan nemu insight menarik… 🤦🏻‍♀️ Aku 🙋🏻 Suami 🤦🏻‍♀️ : sistemnya DJP ini aneh, bukannya fokus ke penjual yg udah 500jt keatas, tapi yg dibawah 500jt juga wajib isi pernyataan omzet kalo gak mau kepotong pajak 🙋🏻: ohh gituu, jadi semua penjual walaupun omzet dibawah 500jt tetep ngisi? 🙋🏻 : intinya DJP mau mendeteksi pedagang sejak dini. Mau omzetmu msh 5jt kek, 10jt kek, pas km ngumpulin pernyataan dan data penghasilan otomatis mereka tau km punya usaha di marketplace. Kalo suatu saat nanti bisnismu berkembang mencapai 500jt, maka kewajibanmu sebagai wajib pajak auto aktif. Sistem defaultnya adalah potong pajak, makanya pernyataan omzet menjadi satu syarat supaya km gak dipotong pajak dan shopee pny dasar hukum knp km gak dipotong pajak. Bonusnya, DJP dpt datamu jg.
B6: 6 | C6: 6 | D6: Temen gue orang pajak. Dia bilang gini: "Bro, orang Indonesia itu takut warisan bukan krn rebutan. Tapi krn PAJAKNYA." Gue tanya: "Emang warisan kena pajak?" Dia ketawa bisa rausan Juta BRO. Satu kalimat dia yg bikin gue langsung telpon nyokap bahas sertifikat rumah.
B7: 7 | C7: 7 | D7: Lulus STAN Tahun 2018, penempatan Kemenkeu, penempatan homebase dari 2019-sekarang, seru-seru aja. Bangun pagi bisa santai sempat olahraga, masuk-pulang tenggo, bisa sambil kuliah, no complaints sih sampai detik ini. Makasih STAN
B8: 25 | C8: 25 | D8: Punya sepupu ASN di Kementerian eselon yang katanya THP paling tinggi se Indonesia. Usia 34thn udah Kepala Seksi, sering dapat penghargaan (gak pernah di post di sosmed taunya dari tante yg post di group wa keluarga 🤭), istrinya dokter spesialis minor, praktek 3 hari aja/minggu sisanya ngurus anak2. Mobil sepupuku keluaran thn 90an beli bekas, kacanya masih diputar. Mobil istrinya city car beli bekas juga. Istrinya gak pernah pake tas branded pakenya tas UMKM
B9: 38 | C9: 38 | D9: Perspektif Internal DJP: Trigger Undangan bagi Wajib Pajak Orang Pribadi. Tahun lalu, tim kami sempat berdiskusi santai dengan salah satu mantan pegawai DJP. Banyak cerita yang kami dapatkan dari perspektif internal, salah satunya adalah trigger dasar mereka untuk mengundang Wajib Pajak melalui SP2DK, Helicopter View yang menjadi dasar analisis dari suatu grup perusahaan atau perusahaan afiliasi, dan masih banyak lagi.
B10: 43 | C10: 43 | D10: Seprtinya bagi mereka mutasi nasional rutin itu berat, apalagi kos+ongkos mudik ga ditanggung samsek+kalo ada pilihan jadi konsultan sepertinya logis milih resign/pindah pemda…
B11: 45 | C11: 45 | D11: saya lebih percaya ada kucing diangkat jadi presiden dari pada percaya pegawai pajak 100% bersih
B12: 51 | C12: 51 | D12: Fyi aja nih bang 1. Tukin djp dari 2015 blm ada kenaikan 2. AR gaada yang lulusan dari sma karena minimal d3
B13: 53 | C13: 53 | D13: Malam ini ngerenung sendiri, bersyukur banget bisa kerja di DJP instansi yg ga ada korupsinya babar blas. Top markotop. Yg resign berarti pengecut kecuali ada kepentingan lain ya. No offense.
B14: 63 | C14: 65 | D14: Satpam: 3jt, 3jt, 3jt; Manajer: 15jt, 15jt, 20jt, 25jt, 30jt; Content Creator: 0, 5jt, 0, 50jt; Pegawai Pajak: 10jt, 10jt, 500jt, 1M, ketangkep.
B15: 66 | C15: 68 | D15: Mutasi bank orang pribadi memang boleh diintip DJP?
B16: 81 | C16: 83 | D16: Membahas dasar resmi DJP menerbitkan SP2DK dan meminta pendapat apakah SP2DK merupakan pengawasan wajar atau membuat wajib pajak takut.
... B44: 260 | C44: 285 | D44: Ironi hidup di negara yang sumber utama penghasilannya dari "malak" rakyat lewat pajak: ​Gaji turun? Langsung dipotong pajak (PPh). ​Sisa gaji buat belanja? Kena PPN 11%. ​Makan di resto? Kena Pajak ​Punya kendaraan? Bayar pajak, pake sisa gaji yang sdh bersih dr pajak. ​Punya rumah? Bayar PBB.
B46: Terisi Pelabel A | D46: =COUNTA(E5:E44) -> 0
B47: Terisi Pelabel B | D47: =COUNTA(F5:F44) -> 0
B48: Sepakat (jumlah) | D48: =SUMPRODUCT((E5:E44<>"")*(F5:F44<>"")*(E5:E44=F5:F44)) -> 0
B49: Persen kesepakatan | D49: =IFERROR(D48/SUMPRODUCT((E5:E44<>"")*(F5:F44<>"")),0) -> 0
B51: Persen kesepakatan di atas hanya untuk pemantauan cepat. Angka yang dilaporkan adalah Krippendorff's alpha, dihitung oleh notebook, karena persentase kesepakatan tidak mengoreksi kesepakatan yang terjadi secara kebetulan.

Sheet Uji Keandalan Akhir
B1: UJI KEANDALAN AKHIR
B2: Uji akhir sesuai Neuendorf (2017): dikerjakan pada subsampel acak lain (50 unit) SELAMA atau SESUDAH pengodean penuh berjalan. Nilai alpha dari lembar inilah yang dilaporkan bersama hasil penelitian. Unit di sini tidak beririsan dengan unit pada uji awal.
B4: ID | C4: No Asli | D4: Isi Thread | E4: PELABEL A | F4: PELABEL B
B5: 10 | C5: 10 | D5: Saya ex-pajak. Saya kabari ga enaknya jadi pegawai pajak: 1. Mutasi Nasional, saya pernah di papua 6 tahun. Harus siap jauh dari keluarga. Pengelolaan keluarga jadi rumit. Mahal pula. 2. Kerja sebagai pemberi sanksi. Waktu itu jabatan saya pemeriksa. Pengusaha indo banyak yang ga siap sama pengujian. Ga ngerti kalo bisnis itu wajib didokumentasikan. Memberi sanksi sama pengusaha nakal adalah kebanggaan, tapi sama yang ga ngerti, jadinya perasaan bersalah. 3. Nanti saya terusin.
B6: 13 | C6: 13 | D6: Tugas DJP tu skrg sulit ya Pajak dan kerelaan org bayar pajak makin tergerus akibat oknum2 yg menggunakan uang pajak rakyat serampangan Gimana org mau rela bayar pajak kalau gak ada lagi trust yg tercpta
B7: 16 | C7: 16 | D7: Isn’t that so the truth. Prefect is boring, it’s the struggle that makes us who we are. -DJP 2025
B8: 19 | C8: 19 | D8: Dulu, suami adalah pegawai Kemen*** D*P dengan THP 2 digit. Setelah 14 tahun, akhirnya memutuskan untuk mengundurkan diri dengan hormat setelah maju mundur, beberapa kali mengambil cuti. Waktu itu, rumah masih ngontrak dan ada tabungan yang hanya cukup buat DP rumah di daerah tangsel. Sudah 5 tahun berlalu...
B9: 27 | C9: 27 | D9: TUKIN pegawai pajak emang rata-rata gede banget ya? Di DJP, yg level pelaksana aja bisa dapat 5 juta sebulan.
B10: 32 | C10: 32 | D10: Ga sepakat...asumsi saya, Dimana2 djp lebih tinggi thp nya dibanding 80 - 90 persen pemda seindonesia
B11: 35 | C11: 35 | D11: Saya di KOMCAD kan lalu di tekan ini itu kak, dari kementerian yg katanya sultan. Tes kesehatan KOMCAD penuh ma-ni-pu-la-si, daripada saya mati kaya yg udh ada...Lalu saya memilih resign sekalian
B12: 40 | C12: 40 | D12: Waah smoga makin bersinar diluar DJP ya kak, makin sukses dan berkah juga usahanya, aamiin. Memang yg bikin deg2an di DJP adalah ketidakpastian waktu & tempat mutasi, LDRan, dan ongkos tambahan yg harus ditanggung karena berjauhan dg kluarga. Saya 3,5 thn LDRan pas penempatan di Batam, alhamdulillah disupport full sama suami jadi bisa seminggu sekali pulang ke Jkt demi ketemu kluarga. Tapi ngga banyak temen2 DJP yg seberuntung saya 😰
B13: 47 | C13: 47 | D13: itulah salah satu alasan saya resign dr DJP, di samping ada alasan lain yg jauh lebih fundamental..bos² carmuk sendiri? udah biasa... mereka cuci tangan? udah biasa juga..
B14: 55 | C14: 55 | D14: 1 hal yang pasti Yang pengecut adalah yang tau itu ga nyaman dan tetap berada disana. Saya resign dari DJP bukan karena pengecut. Ooh iya menambahkan, orang yang berani resign apalagi dari DJP itu udah pasti bukan hanya pegawai yang fokus pada 1 zona aja, dan dipastikan kalo yang resign itu ga ada beban finansial berupa cicilan sih minimal
B15: 57 | C15: 57 | D15: DJP tunangannya sudah paling gede, ga usah cengeng🤣.. instansi lain jg sama aja dgn tunjangan yg jauh lebih kecil
B16: 72 | C16: 74 | D16: DJP itu di bawah Kemenkeu bukan? Atau memang tukinnya berbeda sendiri dibanding direktorat lain di Kemenkeu?
... B54: 264 | C54: 289 | D54: crab mentality di indonesia beneran nyata sih. kemarin aku bagiin POV ku tentang aku PKP dari tahun 2022, udah bayar ppn 11% dari bruto semua transaksi toko onlineku. aku jujur, transparan, sesuai data di toko, biar terhindar dari SP2DK. tau apa yang terjadi? aku live jualan di spam katanya dukung korupsi. upload video dibilang mendukung MBG. diajak buat berhenti bayar pajak. Aku juga kesel korupsi, tp pajak kewajiban. mau tinggal di eropa jg bayar pajak. Mau usaha maju ya bayar pajak.
B56: Terisi Pelabel A | D56: =COUNTA(E5:E54) -> 0
B57: Terisi Pelabel B | D57: =COUNTA(F5:F54) -> 0
B58: Sepakat (jumlah) | D58: =SUMPRODUCT((E5:E54<>"")*(F5:F54<>"")*(E5:E54=F5:F54)) -> 0
B59: Persen kesepakatan | D59: =IFERROR(D58/SUMPRODUCT((E5:E54<>"")*(F5:F54<>"")),0) -> 0
B61: Persen kesepakatan di atas hanya untuk pemantauan cepat. Angka yang dilaporkan adalah Krippendorff's alpha, dihitung oleh notebook, karena persentase kesepakatan tidak mengoreksi kesepakatan yang terjadi secara kebetulan.

Sheet Ringkasan
B2: RINGKASAN PROSES PENGODEAN
B4: Progres pengodean
B5: Kategori | C5: Jumlah | D5: Persen
B6: Positif | C6: =COUNTIF(Relabeling!$H$2:$H$265,B6) -> 0 | D6: =IFERROR(C6/$C$10,0) -> 0
B7: Negatif | C7: =COUNTIF(Relabeling!$H$2:$H$265,B7) -> 0 | D7: =IFERROR(C7/$C$10,0) -> 0
B8: Netral | C8: =COUNTIF(Relabeling!$H$2:$H$265,B8) -> 0 | D8: =IFERROR(C8/$C$10,0) -> 0
B9: Tidak Relevan | C9: =COUNTIF(Relabeling!$H$2:$H$265,B9) -> 0 | D9: =IFERROR(C9/$C$10,0) -> 0
B10: Total sudah dikode | C10: =SUM(C6:C9) -> 0
B11: Belum dikode | C11: =COUNTBLANK(Relabeling!$H$2:$H$265) -> 264
B12: Masuk data latih | C12: =C6+C7+C8 -> 0 | E12: Kategori Tidak Relevan dikeluarkan dari data latih.
B15: Keandalan pengodean
B16: Uji | C16: Persen sepakat | D16: Alpha | E16: Keterangan
B17: Uji awal (pilot) | C17: ='Uji Keandalan Awal'!D49 -> 0 | D17: Dihitung notebook | E17: Sebelum pengodean penuh dimulai
B18: Uji akhir | C18: ='Uji Keandalan Akhir'!D59 -> 0 | D18: Dihitung notebook | E18: Nilai inilah yang dilaporkan bersama hasil
B20: Ambang: alpha >= 0,800 dapat diandalkan; 0,667–0,800 sementara; < 0,667 belum layak.
B23: Perbandingan dengan label lama
B24: Kategori | C24: Label lama | D24: Label baru
B25: Positif | C25: =COUNTIF(Relabeling!$F$2:$F$265,B25) -> 62 | D25: =COUNTIF(Relabeling!$H$2:$H$265,B25) -> 0
B26: Negatif | C26: =COUNTIF(Relabeling!$F$2:$F$265,B26) -> 126 | D26: =COUNTIF(Relabeling!$H$2:$H$265,B26) -> 0
B27: Netral | C27: =COUNTIF(Relabeling!$F$2:$F$265,B27) -> 75 | D27: =COUNTIF(Relabeling!$H$2:$H$265,B27) -> 0
B28: Label berubah | C28: =SUMPRODUCT((Relabeling!$H$2:$H$265<>"")*(LOWER(Relabeling!$H$2:$H$265)<>Relabeling!$F$2:$F$265)) -> 0
B31: Catatan pembersihan data
B32: Unit sampling awal | C32: 289
B33: Duplikat persis dibuang | C33: 25
B34: Unit unik untuk dikode | C34: 264
B35: Teks identik dengan label lama berbeda | C35: 7
B36: Label lama kosong atau tidak valid | C36: 1
B37: Unit tanpa tanggal valid | C37: 95
B38: Kolom Waktu dibuang: 264 dari 289 baris kosong.

Sheet Log Duplikat
A1: No Asli Dibuang | B1: Username | C1: Label Lama | D1: Digabung ke No | E1: Cuplikan Teks
A2: 62 | B2: peaceanloovve | C2: negatif | D2: 51 | E2: Fyi aja nih bang 1. Tukin djp dari 2015 blm ada kenaikan 2. AR gaada yang lulusan dari sma karena minimal d3
A3: 63 | B3: prastowoyustinus | C3: positif | D3: 52 | E3: Beberapa hari ini rame diskusi soal STAN dan resign dari PNS. Saya juga alumnus STAN, pernah bekerja di birokrasi yaitu DJP, dan resign 2010. Kuliah di STAN memang bukan pilihan utama, tapi realistis
A4: 125 | B4: ernandaputra | C4: negatif | D4: 92 | E4: Bentar..bentar.. Kalo dipikir logikanya, kita yang kerja, kita yang bayar pajak. Trus kita juga yang harus ribet ngelaporin. Harusnya pemerintah ga sih yg laporan ke kita, pajak yang uda kita sumbang
A5: 132 | B5: aguyyugaaguy | C5: positif | D5: 91 | E5: To the point aja ya warga thread, Saya penyuluh pajak di salah satu KPP Jakarta. Feel Free dan For Free alias GRATIS. Bagi yg masih bingung masalah per-coretax-an, termasuk cara Lapor SPT, boleh tanya
A6: 135 | B6: ddilady | C6: netral | D6: 104 | E6: serius nanya. aku abis dikasih tau petugas pajak kalo mending wajib pajak nya di non aktifkan aja (soalnya cuma buat aff). biar gausah repot lapor tiap tahun. nah mau tanya kalo di non aktifkan gitu,
A7: 138 | B7: nioald | C7: negatif | D7: 112 | E7: Lagi rame berita Kanwil DJP Jaksel baru aja blokir rekening bank milik 57 wajib pajak. Total saldo yang ketahan di bank nggak main main, tembus 80 miliar rupiah. Banyak pengusaha yang kaget kok bisa k
A8: 144 | B8: wolandgarro | C8: negatif | D8: 17 | E8: 1/ Konflik kepentingan di DJP & KPP udah di level memprihatinkan. Temen gua eks KPP cerita: banyak petugas pajak yang… istrinya ternyata konsultan pajak. Kebayang gak? Di satu sisi dia punya power, di
A9: 149 | B9: aariakbr | C9: negatif | D9: 26 | E9: Kalau sesuai hadist: Pegawai DJP dan bea cukai tidak akan masuk surga
A10: 151 | B10: by_marhentin.ika | C10: netral | D10: 30 | E10: Beberapa hari ini dapet DM dr temen2 internal DJP karena postingan saya seputar edukasi pajak muncul di akun mereka. Rata2 menyemangati karena memang ngga banyak pegawai DJP yg nekat muncul di medsos,
A11: 162 | B11: terajanajunu | C11: netral | D11: 13 | E11: Tugas DJP tu skrg sulit ya Pajak dan kerelaan org bayar pajak makin tergerus akibat oknum2 yg menggunakan uang pajak rakyat serampangan Gimana org mau rela bayar pajak kalau gak ada lagi trust yg terc
A12: 167 | B12: unaisatuzzahro | C12: netral | D12: 19 | E12: Dulu, suami adalah pegawai Kemen*** D*P dengan THP 2 digit. Setelah 14 tahun, akhirnya memutuskan untuk mengundurkan diri dengan hormat setelah maju mundur, beberapa kali mengambil cuti. Waktu itu, ru
A13: 186 | B13: meeyaardouli | C13: netral | D13: 29 | E13: Hampir mustahil sih…. Gaji pegawai djp tinggi itu tujuannya mencegah brain drain supaya pegawainya ngga pada kabur jadi konsultan, pindah jadi tax manager persh swasta, atau pindah ke pemda yg ga tera
... A26: 269 | B26: niarwitya | C26: negatif | D26: 106 | E26: Rasanya pemerentah skrg klo bikin kebijakan pajak grusa grusu ya, ttg coretax, pmk ppn dtp, trs ini peraturan pajak marketplace. Perasaan dulu waktu ppn naik 1 persen ga se grusa grusu ini deh. Ada so
